2017-12-07 15:55:57,752 [Thread-3:123145341300736] [django.request:152] [base:get_response] [WARNING]- Not Found: /user/login/
2017-12-07 17:46:28,164 [Thread-2:123145393844224] [django.request:152] [base:get_response] [WARNING]- Not Found: /getUser
2017-12-07 17:46:53,940 [Thread-2:123145374760960] [django.request:135] [exception:handle_uncaught_exception] [ERROR]- Internal Server Error: /user/getUser
Traceback (most recent call last):
  File "/usr/local/Cellar/pypy/5.8.0/libexec/site-packages/django/core/handlers/exception.py", line 41, in inner
    response = get_response(request)
  File "/usr/local/Cellar/pypy/5.8.0/libexec/site-packages/django/core/handlers/base.py", line 187, in _get_response
    response = self.process_exception_by_middleware(e, request)
  File "/usr/local/Cellar/pypy/5.8.0/libexec/site-packages/django/core/handlers/base.py", line 185, in _get_response
    response = wrapped_callback(request, *callback_args, **callback_kwargs)
  File "/usr/local/Cellar/pypy/5.8.0/libexec/site-packages/django/views/decorators/csrf.py", line 58, in wrapped_view
    return view_func(*args, **kwargs)
  File "/usr/local/Cellar/pypy/5.8.0/libexec/site-packages/django/views/generic/base.py", line 68, in view
    return self.dispatch(request, *args, **kwargs)
  File "/usr/local/Cellar/pypy/5.8.0/libexec/site-packages/rest_framework/views.py", line 489, in dispatch
    response = self.handle_exception(exc)
  File "/usr/local/Cellar/pypy/5.8.0/libexec/site-packages/rest_framework/views.py", line 449, in handle_exception
    self.raise_uncaught_exception(exc)
  File "/usr/local/Cellar/pypy/5.8.0/libexec/site-packages/rest_framework/views.py", line 486, in dispatch
    response = handler(request, *args, **kwargs)
  File "/Users/benson/Projects/MikasonOperBackend/deployuser/views.py", line 141, in post
    raise ParamException('userid')
NameError: global name 'ParamException' is not defined
2017-12-07 18:44:33,608 [Thread-2:123145506902016] [django.request:135] [exception:handle_uncaught_exception] [ERROR]- Internal Server Error: /bussiness/GetBussiness
Traceback (most recent call last):
  File "/usr/local/Cellar/pypy/5.8.0/libexec/site-packages/django/core/handlers/exception.py", line 41, in inner
    response = get_response(request)
  File "/usr/local/Cellar/pypy/5.8.0/libexec/site-packages/django/core/handlers/base.py", line 187, in _get_response
    response = self.process_exception_by_middleware(e, request)
  File "/usr/local/Cellar/pypy/5.8.0/libexec/site-packages/django/core/handlers/base.py", line 185, in _get_response
    response = wrapped_callback(request, *callback_args, **callback_kwargs)
  File "/usr/local/Cellar/pypy/5.8.0/libexec/site-packages/django/views/decorators/csrf.py", line 58, in wrapped_view
    return view_func(*args, **kwargs)
  File "/usr/local/Cellar/pypy/5.8.0/libexec/site-packages/django/views/generic/base.py", line 68, in view
    return self.dispatch(request, *args, **kwargs)
  File "/usr/local/Cellar/pypy/5.8.0/libexec/site-packages/rest_framework/views.py", line 489, in dispatch
    response = self.handle_exception(exc)
  File "/usr/local/Cellar/pypy/5.8.0/libexec/site-packages/rest_framework/views.py", line 449, in handle_exception
    self.raise_uncaught_exception(exc)
  File "/usr/local/Cellar/pypy/5.8.0/libexec/site-packages/rest_framework/views.py", line 486, in dispatch
    response = handler(request, *args, **kwargs)
  File "/Users/benson/Projects/MikasonOperBackend/bussiness/views.py", line 91, in post
    'operator': operator.username,
AttributeError: 'NoneType' object has no attribute 'username'
2017-12-07 18:45:04,504 [Thread-2:123145313849344] [django.request:135] [exception:handle_uncaught_exception] [ERROR]- Internal Server Error: /bussiness/GetBussiness
Traceback (most recent call last):
  File "/usr/local/Cellar/pypy/5.8.0/libexec/site-packages/django/core/handlers/exception.py", line 41, in inner
    response = get_response(request)
  File "/usr/local/Cellar/pypy/5.8.0/libexec/site-packages/django/core/handlers/base.py", line 187, in _get_response
    response = self.process_exception_by_middleware(e, request)
  File "/usr/local/Cellar/pypy/5.8.0/libexec/site-packages/django/core/handlers/base.py", line 185, in _get_response
    response = wrapped_callback(request, *callback_args, **callback_kwargs)
  File "/usr/local/Cellar/pypy/5.8.0/libexec/site-packages/django/views/decorators/csrf.py", line 58, in wrapped_view
    return view_func(*args, **kwargs)
  File "/usr/local/Cellar/pypy/5.8.0/libexec/site-packages/django/views/generic/base.py", line 68, in view
    return self.dispatch(request, *args, **kwargs)
  File "/usr/local/Cellar/pypy/5.8.0/libexec/site-packages/rest_framework/views.py", line 489, in dispatch
    response = self.handle_exception(exc)
  File "/usr/local/Cellar/pypy/5.8.0/libexec/site-packages/rest_framework/views.py", line 449, in handle_exception
    self.raise_uncaught_exception(exc)
  File "/usr/local/Cellar/pypy/5.8.0/libexec/site-packages/rest_framework/views.py", line 486, in dispatch
    response = handler(request, *args, **kwargs)
  File "/Users/benson/Projects/MikasonOperBackend/bussiness/views.py", line 91, in post
    'operator': operator.username,
AttributeError: 'dict' object has no attribute 'username'
2017-12-07 18:46:54,596 [Thread-2:123145416777728] [django.request:135] [exception:handle_uncaught_exception] [ERROR]- Internal Server Error: /bussiness/GetBussiness
Traceback (most recent call last):
  File "/usr/local/Cellar/pypy/5.8.0/libexec/site-packages/django/core/handlers/exception.py", line 41, in inner
    response = get_response(request)
  File "/usr/local/Cellar/pypy/5.8.0/libexec/site-packages/django/core/handlers/base.py", line 187, in _get_response
    response = self.process_exception_by_middleware(e, request)
  File "/usr/local/Cellar/pypy/5.8.0/libexec/site-packages/django/core/handlers/base.py", line 185, in _get_response
    response = wrapped_callback(request, *callback_args, **callback_kwargs)
  File "/usr/local/Cellar/pypy/5.8.0/libexec/site-packages/django/views/decorators/csrf.py", line 58, in wrapped_view
    return view_func(*args, **kwargs)
  File "/usr/local/Cellar/pypy/5.8.0/libexec/site-packages/django/views/generic/base.py", line 68, in view
    return self.dispatch(request, *args, **kwargs)
  File "/usr/local/Cellar/pypy/5.8.0/libexec/site-packages/rest_framework/views.py", line 489, in dispatch
    response = self.handle_exception(exc)
  File "/usr/local/Cellar/pypy/5.8.0/libexec/site-packages/rest_framework/views.py", line 449, in handle_exception
    self.raise_uncaught_exception(exc)
  File "/usr/local/Cellar/pypy/5.8.0/libexec/site-packages/rest_framework/views.py", line 486, in dispatch
    response = handler(request, *args, **kwargs)
  File "/Users/benson/Projects/MikasonOperBackend/bussiness/views.py", line 94, in post
    'creator': bus.creator
AttributeError: 'QuerySet' object has no attribute 'creator'
2017-12-07 18:46:57,579 [Thread-3:123145416777728] [django.request:135] [exception:handle_uncaught_exception] [ERROR]- Internal Server Error: /bussiness/GetBussiness
Traceback (most recent call last):
  File "/usr/local/Cellar/pypy/5.8.0/libexec/site-packages/django/core/handlers/exception.py", line 41, in inner
    response = get_response(request)
  File "/usr/local/Cellar/pypy/5.8.0/libexec/site-packages/django/core/handlers/base.py", line 187, in _get_response
    response = self.process_exception_by_middleware(e, request)
  File "/usr/local/Cellar/pypy/5.8.0/libexec/site-packages/django/core/handlers/base.py", line 185, in _get_response
    response = wrapped_callback(request, *callback_args, **callback_kwargs)
  File "/usr/local/Cellar/pypy/5.8.0/libexec/site-packages/django/views/decorators/csrf.py", line 58, in wrapped_view
    return view_func(*args, **kwargs)
  File "/usr/local/Cellar/pypy/5.8.0/libexec/site-packages/django/views/generic/base.py", line 68, in view
    return self.dispatch(request, *args, **kwargs)
  File "/usr/local/Cellar/pypy/5.8.0/libexec/site-packages/rest_framework/views.py", line 489, in dispatch
    response = self.handle_exception(exc)
  File "/usr/local/Cellar/pypy/5.8.0/libexec/site-packages/rest_framework/views.py", line 449, in handle_exception
    self.raise_uncaught_exception(exc)
  File "/usr/local/Cellar/pypy/5.8.0/libexec/site-packages/rest_framework/views.py", line 486, in dispatch
    response = handler(request, *args, **kwargs)
  File "/Users/benson/Projects/MikasonOperBackend/bussiness/views.py", line 94, in post
    'creator': bus.creator
AttributeError: 'QuerySet' object has no attribute 'creator'
2017-12-07 18:49:14,485 [Thread-4:123145416777728] [django.request:135] [exception:handle_uncaught_exception] [ERROR]- Internal Server Error: /bussiness/GetBussiness
Traceback (most recent call last):
  File "/usr/local/Cellar/pypy/5.8.0/libexec/site-packages/django/core/handlers/exception.py", line 41, in inner
    response = get_response(request)
  File "/usr/local/Cellar/pypy/5.8.0/libexec/site-packages/django/core/handlers/base.py", line 187, in _get_response
    response = self.process_exception_by_middleware(e, request)
  File "/usr/local/Cellar/pypy/5.8.0/libexec/site-packages/django/core/handlers/base.py", line 185, in _get_response
    response = wrapped_callback(request, *callback_args, **callback_kwargs)
  File "/usr/local/Cellar/pypy/5.8.0/libexec/site-packages/django/views/decorators/csrf.py", line 58, in wrapped_view
    return view_func(*args, **kwargs)
  File "/usr/local/Cellar/pypy/5.8.0/libexec/site-packages/django/views/generic/base.py", line 68, in view
    return self.dispatch(request, *args, **kwargs)
  File "/usr/local/Cellar/pypy/5.8.0/libexec/site-packages/rest_framework/views.py", line 489, in dispatch
    response = self.handle_exception(exc)
  File "/usr/local/Cellar/pypy/5.8.0/libexec/site-packages/rest_framework/views.py", line 449, in handle_exception
    self.raise_uncaught_exception(exc)
  File "/usr/local/Cellar/pypy/5.8.0/libexec/site-packages/rest_framework/views.py", line 486, in dispatch
    response = handler(request, *args, **kwargs)
  File "/Users/benson/Projects/MikasonOperBackend/bussiness/views.py", line 94, in post
    'creator': bus.creator
AttributeError: 'QuerySet' object has no attribute 'creator'
2017-12-07 18:50:58,596 [Thread-2:123145493397504] [django.request:135] [exception:handle_uncaught_exception] [ERROR]- Internal Server Error: /bussiness/GetBussiness
Traceback (most recent call last):
  File "/usr/local/Cellar/pypy/5.8.0/libexec/site-packages/django/core/handlers/exception.py", line 41, in inner
    response = get_response(request)
  File "/usr/local/Cellar/pypy/5.8.0/libexec/site-packages/django/core/handlers/base.py", line 187, in _get_response
    response = self.process_exception_by_middleware(e, request)
  File "/usr/local/Cellar/pypy/5.8.0/libexec/site-packages/django/core/handlers/base.py", line 185, in _get_response
    response = wrapped_callback(request, *callback_args, **callback_kwargs)
  File "/usr/local/Cellar/pypy/5.8.0/libexec/site-packages/django/views/decorators/csrf.py", line 58, in wrapped_view
    return view_func(*args, **kwargs)
  File "/usr/local/Cellar/pypy/5.8.0/libexec/site-packages/django/views/generic/base.py", line 68, in view
    return self.dispatch(request, *args, **kwargs)
  File "/usr/local/Cellar/pypy/5.8.0/libexec/site-packages/rest_framework/views.py", line 489, in dispatch
    response = self.handle_exception(exc)
  File "/usr/local/Cellar/pypy/5.8.0/libexec/site-packages/rest_framework/views.py", line 449, in handle_exception
    self.raise_uncaught_exception(exc)
  File "/usr/local/Cellar/pypy/5.8.0/libexec/site-packages/rest_framework/views.py", line 486, in dispatch
    response = handler(request, *args, **kwargs)
  File "/Users/benson/Projects/MikasonOperBackend/bussiness/views.py", line 94, in post
    'hostnum': bus.hostNum,
AttributeError: 'Bussiness' object has no attribute 'hostNum'
2017-12-07 18:51:02,762 [Thread-3:123145493397504] [django.request:135] [exception:handle_uncaught_exception] [ERROR]- Internal Server Error: /bussiness/GetBussiness
Traceback (most recent call last):
  File "/usr/local/Cellar/pypy/5.8.0/libexec/site-packages/django/core/handlers/exception.py", line 41, in inner
    response = get_response(request)
  File "/usr/local/Cellar/pypy/5.8.0/libexec/site-packages/django/core/handlers/base.py", line 187, in _get_response
    response = self.process_exception_by_middleware(e, request)
  File "/usr/local/Cellar/pypy/5.8.0/libexec/site-packages/django/core/handlers/base.py", line 185, in _get_response
    response = wrapped_callback(request, *callback_args, **callback_kwargs)
  File "/usr/local/Cellar/pypy/5.8.0/libexec/site-packages/django/views/decorators/csrf.py", line 58, in wrapped_view
    return view_func(*args, **kwargs)
  File "/usr/local/Cellar/pypy/5.8.0/libexec/site-packages/django/views/generic/base.py", line 68, in view
    return self.dispatch(request, *args, **kwargs)
  File "/usr/local/Cellar/pypy/5.8.0/libexec/site-packages/rest_framework/views.py", line 489, in dispatch
    response = self.handle_exception(exc)
  File "/usr/local/Cellar/pypy/5.8.0/libexec/site-packages/rest_framework/views.py", line 449, in handle_exception
    self.raise_uncaught_exception(exc)
  File "/usr/local/Cellar/pypy/5.8.0/libexec/site-packages/rest_framework/views.py", line 486, in dispatch
    response = handler(request, *args, **kwargs)
  File "/Users/benson/Projects/MikasonOperBackend/bussiness/views.py", line 94, in post
    'hostnum': bus.hostNum,
AttributeError: 'Bussiness' object has no attribute 'hostNum'
2017-12-07 18:51:24,642 [Thread-2:123145336164352] [django.request:135] [exception:handle_uncaught_exception] [ERROR]- Internal Server Error: /bussiness/GetBussiness
Traceback (most recent call last):
  File "/usr/local/Cellar/pypy/5.8.0/libexec/site-packages/django/core/handlers/exception.py", line 41, in inner
    response = get_response(request)
  File "/usr/local/Cellar/pypy/5.8.0/libexec/site-packages/django/core/handlers/base.py", line 187, in _get_response
    response = self.process_exception_by_middleware(e, request)
  File "/usr/local/Cellar/pypy/5.8.0/libexec/site-packages/django/core/handlers/base.py", line 185, in _get_response
    response = wrapped_callback(request, *callback_args, **callback_kwargs)
  File "/usr/local/Cellar/pypy/5.8.0/libexec/site-packages/django/views/decorators/csrf.py", line 58, in wrapped_view
    return view_func(*args, **kwargs)
  File "/usr/local/Cellar/pypy/5.8.0/libexec/site-packages/django/views/generic/base.py", line 68, in view
    return self.dispatch(request, *args, **kwargs)
  File "/usr/local/Cellar/pypy/5.8.0/libexec/site-packages/rest_framework/views.py", line 489, in dispatch
    response = self.handle_exception(exc)
  File "/usr/local/Cellar/pypy/5.8.0/libexec/site-packages/rest_framework/views.py", line 449, in handle_exception
    self.raise_uncaught_exception(exc)
  File "/usr/local/Cellar/pypy/5.8.0/libexec/site-packages/rest_framework/views.py", line 486, in dispatch
    response = handler(request, *args, **kwargs)
  File "/Users/benson/Projects/MikasonOperBackend/bussiness/views.py", line 94, in post
    'hostnum': bus.hostNum,
AttributeError: 'Bussiness' object has no attribute 'hostNum'
2017-12-07 18:51:37,230 [Thread-2:123145405108224] [django.request:135] [exception:handle_uncaught_exception] [ERROR]- Internal Server Error: /bussiness/GetBussiness
Traceback (most recent call last):
  File "/usr/local/Cellar/pypy/5.8.0/libexec/site-packages/django/core/handlers/exception.py", line 41, in inner
    response = get_response(request)
  File "/usr/local/Cellar/pypy/5.8.0/libexec/site-packages/django/core/handlers/base.py", line 187, in _get_response
    response = self.process_exception_by_middleware(e, request)
  File "/usr/local/Cellar/pypy/5.8.0/libexec/site-packages/django/core/handlers/base.py", line 185, in _get_response
    response = wrapped_callback(request, *callback_args, **callback_kwargs)
  File "/usr/local/Cellar/pypy/5.8.0/libexec/site-packages/django/views/decorators/csrf.py", line 58, in wrapped_view
    return view_func(*args, **kwargs)
  File "/usr/local/Cellar/pypy/5.8.0/libexec/site-packages/django/views/generic/base.py", line 68, in view
    return self.dispatch(request, *args, **kwargs)
  File "/usr/local/Cellar/pypy/5.8.0/libexec/site-packages/rest_framework/views.py", line 489, in dispatch
    response = self.handle_exception(exc)
  File "/usr/local/Cellar/pypy/5.8.0/libexec/site-packages/rest_framework/views.py", line 449, in handle_exception
    self.raise_uncaught_exception(exc)
  File "/usr/local/Cellar/pypy/5.8.0/libexec/site-packages/rest_framework/views.py", line 486, in dispatch
    response = handler(request, *args, **kwargs)
  File "/Users/benson/Projects/MikasonOperBackend/bussiness/views.py", line 94, in post
    'hostnum': bus.hostNum,
AttributeError: 'Bussiness' object has no attribute 'hostNum'
2017-12-07 18:52:01,158 [Thread-2:123145359437824] [django.request:135] [exception:handle_uncaught_exception] [ERROR]- Internal Server Error: /bussiness/GetBussiness
Traceback (most recent call last):
  File "/usr/local/Cellar/pypy/5.8.0/libexec/site-packages/django/core/handlers/exception.py", line 41, in inner
    response = get_response(request)
  File "/usr/local/Cellar/pypy/5.8.0/libexec/site-packages/django/core/handlers/base.py", line 187, in _get_response
    response = self.process_exception_by_middleware(e, request)
  File "/usr/local/Cellar/pypy/5.8.0/libexec/site-packages/django/core/handlers/base.py", line 185, in _get_response
    response = wrapped_callback(request, *callback_args, **callback_kwargs)
  File "/usr/local/Cellar/pypy/5.8.0/libexec/site-packages/django/views/decorators/csrf.py", line 58, in wrapped_view
    return view_func(*args, **kwargs)
  File "/usr/local/Cellar/pypy/5.8.0/libexec/site-packages/django/views/generic/base.py", line 68, in view
    return self.dispatch(request, *args, **kwargs)
  File "/usr/local/Cellar/pypy/5.8.0/libexec/site-packages/rest_framework/views.py", line 489, in dispatch
    response = self.handle_exception(exc)
  File "/usr/local/Cellar/pypy/5.8.0/libexec/site-packages/rest_framework/views.py", line 449, in handle_exception
    self.raise_uncaught_exception(exc)
  File "/usr/local/Cellar/pypy/5.8.0/libexec/site-packages/rest_framework/views.py", line 486, in dispatch
    response = handler(request, *args, **kwargs)
  File "/Users/benson/Projects/MikasonOperBackend/bussiness/views.py", line 94, in post
    'hostnum': bus.hostNum,
AttributeError: 'Bussiness' object has no attribute 'hostNum'
2017-12-07 18:52:42,784 [Thread-2:123145337925632] [django.request:135] [exception:handle_uncaught_exception] [ERROR]- Internal Server Error: /bussiness/GetBussiness
Traceback (most recent call last):
  File "/usr/local/Cellar/pypy/5.8.0/libexec/site-packages/django/core/handlers/exception.py", line 41, in inner
    response = get_response(request)
  File "/usr/local/Cellar/pypy/5.8.0/libexec/site-packages/django/core/handlers/base.py", line 187, in _get_response
    response = self.process_exception_by_middleware(e, request)
  File "/usr/local/Cellar/pypy/5.8.0/libexec/site-packages/django/core/handlers/base.py", line 185, in _get_response
    response = wrapped_callback(request, *callback_args, **callback_kwargs)
  File "/usr/local/Cellar/pypy/5.8.0/libexec/site-packages/django/views/decorators/csrf.py", line 58, in wrapped_view
    return view_func(*args, **kwargs)
  File "/usr/local/Cellar/pypy/5.8.0/libexec/site-packages/django/views/generic/base.py", line 68, in view
    return self.dispatch(request, *args, **kwargs)
  File "/usr/local/Cellar/pypy/5.8.0/libexec/site-packages/rest_framework/views.py", line 489, in dispatch
    response = self.handle_exception(exc)
  File "/usr/local/Cellar/pypy/5.8.0/libexec/site-packages/rest_framework/views.py", line 449, in handle_exception
    self.raise_uncaught_exception(exc)
  File "/usr/local/Cellar/pypy/5.8.0/libexec/site-packages/rest_framework/views.py", line 486, in dispatch
    response = handler(request, *args, **kwargs)
  File "/Users/benson/Projects/MikasonOperBackend/bussiness/views.py", line 94, in post
    'operator': operator.get('username'),
AttributeError: 'Bussiness' object has no attribute 'hostNum'
2017-12-07 18:52:43,837 [Thread-3:123145337925632] [django.request:135] [exception:handle_uncaught_exception] [ERROR]- Internal Server Error: /bussiness/GetBussiness
Traceback (most recent call last):
  File "/usr/local/Cellar/pypy/5.8.0/libexec/site-packages/django/core/handlers/exception.py", line 41, in inner
    response = get_response(request)
  File "/usr/local/Cellar/pypy/5.8.0/libexec/site-packages/django/core/handlers/base.py", line 187, in _get_response
    response = self.process_exception_by_middleware(e, request)
  File "/usr/local/Cellar/pypy/5.8.0/libexec/site-packages/django/core/handlers/base.py", line 185, in _get_response
    response = wrapped_callback(request, *callback_args, **callback_kwargs)
  File "/usr/local/Cellar/pypy/5.8.0/libexec/site-packages/django/views/decorators/csrf.py", line 58, in wrapped_view
    return view_func(*args, **kwargs)
  File "/usr/local/Cellar/pypy/5.8.0/libexec/site-packages/django/views/generic/base.py", line 68, in view
    return self.dispatch(request, *args, **kwargs)
  File "/usr/local/Cellar/pypy/5.8.0/libexec/site-packages/rest_framework/views.py", line 489, in dispatch
    response = self.handle_exception(exc)
  File "/usr/local/Cellar/pypy/5.8.0/libexec/site-packages/rest_framework/views.py", line 449, in handle_exception
    self.raise_uncaught_exception(exc)
  File "/usr/local/Cellar/pypy/5.8.0/libexec/site-packages/rest_framework/views.py", line 486, in dispatch
    response = handler(request, *args, **kwargs)
  File "/Users/benson/Projects/MikasonOperBackend/bussiness/views.py", line 94, in post
    'operator': operator.get('username'),
AttributeError: 'Bussiness' object has no attribute 'hostNum'
2017-12-07 18:52:44,715 [Thread-4:123145337925632] [django.request:135] [exception:handle_uncaught_exception] [ERROR]- Internal Server Error: /bussiness/GetBussiness
Traceback (most recent call last):
  File "/usr/local/Cellar/pypy/5.8.0/libexec/site-packages/django/core/handlers/exception.py", line 41, in inner
    response = get_response(request)
  File "/usr/local/Cellar/pypy/5.8.0/libexec/site-packages/django/core/handlers/base.py", line 187, in _get_response
    response = self.process_exception_by_middleware(e, request)
  File "/usr/local/Cellar/pypy/5.8.0/libexec/site-packages/django/core/handlers/base.py", line 185, in _get_response
    response = wrapped_callback(request, *callback_args, **callback_kwargs)
  File "/usr/local/Cellar/pypy/5.8.0/libexec/site-packages/django/views/decorators/csrf.py", line 58, in wrapped_view
    return view_func(*args, **kwargs)
  File "/usr/local/Cellar/pypy/5.8.0/libexec/site-packages/django/views/generic/base.py", line 68, in view
    return self.dispatch(request, *args, **kwargs)
  File "/usr/local/Cellar/pypy/5.8.0/libexec/site-packages/rest_framework/views.py", line 489, in dispatch
    response = self.handle_exception(exc)
  File "/usr/local/Cellar/pypy/5.8.0/libexec/site-packages/rest_framework/views.py", line 449, in handle_exception
    self.raise_uncaught_exception(exc)
  File "/usr/local/Cellar/pypy/5.8.0/libexec/site-packages/rest_framework/views.py", line 486, in dispatch
    response = handler(request, *args, **kwargs)
  File "/Users/benson/Projects/MikasonOperBackend/bussiness/views.py", line 94, in post
    'operator': operator.get('username'),
AttributeError: 'Bussiness' object has no attribute 'hostNum'
2017-12-07 18:52:45,449 [Thread-5:123145337925632] [django.request:135] [exception:handle_uncaught_exception] [ERROR]- Internal Server Error: /bussiness/GetBussiness
Traceback (most recent call last):
  File "/usr/local/Cellar/pypy/5.8.0/libexec/site-packages/django/core/handlers/exception.py", line 41, in inner
    response = get_response(request)
  File "/usr/local/Cellar/pypy/5.8.0/libexec/site-packages/django/core/handlers/base.py", line 187, in _get_response
    response = self.process_exception_by_middleware(e, request)
  File "/usr/local/Cellar/pypy/5.8.0/libexec/site-packages/django/core/handlers/base.py", line 185, in _get_response
    response = wrapped_callback(request, *callback_args, **callback_kwargs)
  File "/usr/local/Cellar/pypy/5.8.0/libexec/site-packages/django/views/decorators/csrf.py", line 58, in wrapped_view
    return view_func(*args, **kwargs)
  File "/usr/local/Cellar/pypy/5.8.0/libexec/site-packages/django/views/generic/base.py", line 68, in view
    return self.dispatch(request, *args, **kwargs)
  File "/usr/local/Cellar/pypy/5.8.0/libexec/site-packages/rest_framework/views.py", line 489, in dispatch
    response = self.handle_exception(exc)
  File "/usr/local/Cellar/pypy/5.8.0/libexec/site-packages/rest_framework/views.py", line 449, in handle_exception
    self.raise_uncaught_exception(exc)
  File "/usr/local/Cellar/pypy/5.8.0/libexec/site-packages/rest_framework/views.py", line 486, in dispatch
    response = handler(request, *args, **kwargs)
  File "/Users/benson/Projects/MikasonOperBackend/bussiness/views.py", line 94, in post
    'operator': operator.get('username'),
AttributeError: 'Bussiness' object has no attribute 'hostNum'
2017-12-07 18:52:46,167 [Thread-6:123145337925632] [django.request:135] [exception:handle_uncaught_exception] [ERROR]- Internal Server Error: /bussiness/GetBussiness
Traceback (most recent call last):
  File "/usr/local/Cellar/pypy/5.8.0/libexec/site-packages/django/core/handlers/exception.py", line 41, in inner
    response = get_response(request)
  File "/usr/local/Cellar/pypy/5.8.0/libexec/site-packages/django/core/handlers/base.py", line 187, in _get_response
    response = self.process_exception_by_middleware(e, request)
  File "/usr/local/Cellar/pypy/5.8.0/libexec/site-packages/django/core/handlers/base.py", line 185, in _get_response
    response = wrapped_callback(request, *callback_args, **callback_kwargs)
  File "/usr/local/Cellar/pypy/5.8.0/libexec/site-packages/django/views/decorators/csrf.py", line 58, in wrapped_view
    return view_func(*args, **kwargs)
  File "/usr/local/Cellar/pypy/5.8.0/libexec/site-packages/django/views/generic/base.py", line 68, in view
    return self.dispatch(request, *args, **kwargs)
  File "/usr/local/Cellar/pypy/5.8.0/libexec/site-packages/rest_framework/views.py", line 489, in dispatch
    response = self.handle_exception(exc)
  File "/usr/local/Cellar/pypy/5.8.0/libexec/site-packages/rest_framework/views.py", line 449, in handle_exception
    self.raise_uncaught_exception(exc)
  File "/usr/local/Cellar/pypy/5.8.0/libexec/site-packages/rest_framework/views.py", line 486, in dispatch
    response = handler(request, *args, **kwargs)
  File "/Users/benson/Projects/MikasonOperBackend/bussiness/views.py", line 94, in post
    'operator': operator.get('username'),
AttributeError: 'Bussiness' object has no attribute 'hostNum'
2017-12-07 18:52:52,447 [Thread-7:123145337925632] [django.request:135] [exception:handle_uncaught_exception] [ERROR]- Internal Server Error: /bussiness/GetBussiness
Traceback (most recent call last):
  File "/usr/local/Cellar/pypy/5.8.0/libexec/site-packages/django/core/handlers/exception.py", line 41, in inner
    response = get_response(request)
  File "/usr/local/Cellar/pypy/5.8.0/libexec/site-packages/django/core/handlers/base.py", line 187, in _get_response
    response = self.process_exception_by_middleware(e, request)
  File "/usr/local/Cellar/pypy/5.8.0/libexec/site-packages/django/core/handlers/base.py", line 185, in _get_response
    response = wrapped_callback(request, *callback_args, **callback_kwargs)
  File "/usr/local/Cellar/pypy/5.8.0/libexec/site-packages/django/views/decorators/csrf.py", line 58, in wrapped_view
    return view_func(*args, **kwargs)
  File "/usr/local/Cellar/pypy/5.8.0/libexec/site-packages/django/views/generic/base.py", line 68, in view
    return self.dispatch(request, *args, **kwargs)
  File "/usr/local/Cellar/pypy/5.8.0/libexec/site-packages/rest_framework/views.py", line 489, in dispatch
    response = self.handle_exception(exc)
  File "/usr/local/Cellar/pypy/5.8.0/libexec/site-packages/rest_framework/views.py", line 449, in handle_exception
    self.raise_uncaught_exception(exc)
  File "/usr/local/Cellar/pypy/5.8.0/libexec/site-packages/rest_framework/views.py", line 486, in dispatch
    response = handler(request, *args, **kwargs)
  File "/Users/benson/Projects/MikasonOperBackend/bussiness/views.py", line 94, in post
    'operator': operator.get('username'),
AttributeError: 'Bussiness' object has no attribute 'hostNum'
2017-12-07 18:53:13,102 [Thread-2:123145404379136] [django.request:135] [exception:handle_uncaught_exception] [ERROR]- Internal Server Error: /bussiness/GetBussiness
Traceback (most recent call last):
  File "/usr/local/Cellar/pypy/5.8.0/libexec/site-packages/django/core/handlers/exception.py", line 41, in inner
    response = get_response(request)
  File "/usr/local/Cellar/pypy/5.8.0/libexec/site-packages/django/core/handlers/base.py", line 187, in _get_response
    response = self.process_exception_by_middleware(e, request)
  File "/usr/local/Cellar/pypy/5.8.0/libexec/site-packages/django/core/handlers/base.py", line 185, in _get_response
    response = wrapped_callback(request, *callback_args, **callback_kwargs)
  File "/usr/local/Cellar/pypy/5.8.0/libexec/site-packages/django/views/decorators/csrf.py", line 58, in wrapped_view
    return view_func(*args, **kwargs)
  File "/usr/local/Cellar/pypy/5.8.0/libexec/site-packages/django/views/generic/base.py", line 68, in view
    return self.dispatch(request, *args, **kwargs)
  File "/usr/local/Cellar/pypy/5.8.0/libexec/site-packages/rest_framework/views.py", line 489, in dispatch
    response = self.handle_exception(exc)
  File "/usr/local/Cellar/pypy/5.8.0/libexec/site-packages/rest_framework/views.py", line 449, in handle_exception
    self.raise_uncaught_exception(exc)
  File "/usr/local/Cellar/pypy/5.8.0/libexec/site-packages/rest_framework/views.py", line 486, in dispatch
    response = handler(request, *args, **kwargs)
  File "/Users/benson/Projects/MikasonOperBackend/bussiness/views.py", line 93, in post
    'hostnum': bus.hostNum,
AttributeError: 'Bussiness' object has no attribute 'hostNum'
2017-12-07 18:55:14,205 [Thread-2:123145402572800] [django.request:135] [exception:handle_uncaught_exception] [ERROR]- Internal Server Error: /bussiness/GetBussiness
Traceback (most recent call last):
  File "/usr/local/Cellar/pypy/5.8.0/libexec/site-packages/django/core/handlers/exception.py", line 41, in inner
    response = get_response(request)
  File "/usr/local/Cellar/pypy/5.8.0/libexec/site-packages/django/core/handlers/base.py", line 187, in _get_response
    response = self.process_exception_by_middleware(e, request)
  File "/usr/local/Cellar/pypy/5.8.0/libexec/site-packages/django/core/handlers/base.py", line 185, in _get_response
    response = wrapped_callback(request, *callback_args, **callback_kwargs)
  File "/usr/local/Cellar/pypy/5.8.0/libexec/site-packages/django/views/decorators/csrf.py", line 58, in wrapped_view
    return view_func(*args, **kwargs)
  File "/usr/local/Cellar/pypy/5.8.0/libexec/site-packages/django/views/generic/base.py", line 68, in view
    return self.dispatch(request, *args, **kwargs)
  File "/usr/local/Cellar/pypy/5.8.0/libexec/site-packages/rest_framework/views.py", line 489, in dispatch
    response = self.handle_exception(exc)
  File "/usr/local/Cellar/pypy/5.8.0/libexec/site-packages/rest_framework/views.py", line 449, in handle_exception
    self.raise_uncaught_exception(exc)
  File "/usr/local/Cellar/pypy/5.8.0/libexec/site-packages/rest_framework/views.py", line 486, in dispatch
    response = handler(request, *args, **kwargs)
  File "/Users/benson/Projects/MikasonOperBackend/bussiness/views.py", line 86, in post
    for bus in serializer.data:
UnboundLocalError: local variable 'serializer' referenced before assignment
2017-12-07 18:55:21,761 [Thread-2:123145475428352] [django.request:135] [exception:handle_uncaught_exception] [ERROR]- Internal Server Error: /bussiness/GetBussiness
Traceback (most recent call last):
  File "/usr/local/Cellar/pypy/5.8.0/libexec/site-packages/django/core/handlers/exception.py", line 41, in inner
    response = get_response(request)
  File "/usr/local/Cellar/pypy/5.8.0/libexec/site-packages/django/core/handlers/base.py", line 187, in _get_response
    response = self.process_exception_by_middleware(e, request)
  File "/usr/local/Cellar/pypy/5.8.0/libexec/site-packages/django/core/handlers/base.py", line 185, in _get_response
    response = wrapped_callback(request, *callback_args, **callback_kwargs)
  File "/usr/local/Cellar/pypy/5.8.0/libexec/site-packages/django/views/decorators/csrf.py", line 58, in wrapped_view
    return view_func(*args, **kwargs)
  File "/usr/local/Cellar/pypy/5.8.0/libexec/site-packages/django/views/generic/base.py", line 68, in view
    return self.dispatch(request, *args, **kwargs)
  File "/usr/local/Cellar/pypy/5.8.0/libexec/site-packages/rest_framework/views.py", line 489, in dispatch
    response = self.handle_exception(exc)
  File "/usr/local/Cellar/pypy/5.8.0/libexec/site-packages/rest_framework/views.py", line 449, in handle_exception
    self.raise_uncaught_exception(exc)
  File "/usr/local/Cellar/pypy/5.8.0/libexec/site-packages/rest_framework/views.py", line 486, in dispatch
    response = handler(request, *args, **kwargs)
  File "/Users/benson/Projects/MikasonOperBackend/bussiness/views.py", line 87, in post
    operator = self.get_user(bus.operatorid)
AttributeError: 'OrderedDict' object has no attribute 'operatorid'
2017-12-07 18:55:25,271 [Thread-3:123145475428352] [django.request:135] [exception:handle_uncaught_exception] [ERROR]- Internal Server Error: /bussiness/GetBussiness
Traceback (most recent call last):
  File "/usr/local/Cellar/pypy/5.8.0/libexec/site-packages/django/core/handlers/exception.py", line 41, in inner
    response = get_response(request)
  File "/usr/local/Cellar/pypy/5.8.0/libexec/site-packages/django/core/handlers/base.py", line 187, in _get_response
    response = self.process_exception_by_middleware(e, request)
  File "/usr/local/Cellar/pypy/5.8.0/libexec/site-packages/django/core/handlers/base.py", line 185, in _get_response
    response = wrapped_callback(request, *callback_args, **callback_kwargs)
  File "/usr/local/Cellar/pypy/5.8.0/libexec/site-packages/django/views/decorators/csrf.py", line 58, in wrapped_view
    return view_func(*args, **kwargs)
  File "/usr/local/Cellar/pypy/5.8.0/libexec/site-packages/django/views/generic/base.py", line 68, in view
    return self.dispatch(request, *args, **kwargs)
  File "/usr/local/Cellar/pypy/5.8.0/libexec/site-packages/rest_framework/views.py", line 489, in dispatch
    response = self.handle_exception(exc)
  File "/usr/local/Cellar/pypy/5.8.0/libexec/site-packages/rest_framework/views.py", line 449, in handle_exception
    self.raise_uncaught_exception(exc)
  File "/usr/local/Cellar/pypy/5.8.0/libexec/site-packages/rest_framework/views.py", line 486, in dispatch
    response = handler(request, *args, **kwargs)
  File "/Users/benson/Projects/MikasonOperBackend/bussiness/views.py", line 87, in post
    operator = self.get_user(bus.operatorid)
AttributeError: 'OrderedDict' object has no attribute 'operatorid'
2017-12-08 14:44:51,072 [Thread-3:123145326198784] [django.request:135] [exception:handle_uncaught_exception] [ERROR]- Internal Server Error: /server/CreateCluster
Traceback (most recent call last):
  File "/usr/local/Cellar/pypy/5.8.0/libexec/site-packages/django/core/handlers/exception.py", line 41, in inner
    response = get_response(request)
  File "/usr/local/Cellar/pypy/5.8.0/libexec/site-packages/django/core/handlers/base.py", line 187, in _get_response
    response = self.process_exception_by_middleware(e, request)
  File "/usr/local/Cellar/pypy/5.8.0/libexec/site-packages/django/core/handlers/base.py", line 185, in _get_response
    response = wrapped_callback(request, *callback_args, **callback_kwargs)
  File "/usr/local/Cellar/pypy/5.8.0/libexec/site-packages/django/views/decorators/csrf.py", line 58, in wrapped_view
    return view_func(*args, **kwargs)
  File "/usr/local/Cellar/pypy/5.8.0/libexec/site-packages/django/views/generic/base.py", line 68, in view
    return self.dispatch(request, *args, **kwargs)
  File "/usr/local/Cellar/pypy/5.8.0/libexec/site-packages/rest_framework/views.py", line 489, in dispatch
    response = self.handle_exception(exc)
  File "/usr/local/Cellar/pypy/5.8.0/libexec/site-packages/rest_framework/views.py", line 449, in handle_exception
    self.raise_uncaught_exception(exc)
  File "/usr/local/Cellar/pypy/5.8.0/libexec/site-packages/rest_framework/views.py", line 486, in dispatch
    response = handler(request, *args, **kwargs)
  File "/Users/benson/Projects/MikasonOperBackend/server/cluster_api_views.py", line 25, in post
    serializer.save()
  File "/usr/local/Cellar/pypy/5.8.0/libexec/site-packages/rest_framework/serializers.py", line 215, in save
    self.instance = self.create(validated_data)
  File "/usr/local/Cellar/pypy/5.8.0/libexec/site-packages/rest_framework/serializers.py", line 916, in create
    instance = ModelClass.objects.create(**validated_data)
  File "/usr/local/Cellar/pypy/5.8.0/libexec/site-packages/django/db/models/manager.py", line 85, in manager_method
    return getattr(self.get_queryset(), name)(*args, **kwargs)
  File "/usr/local/Cellar/pypy/5.8.0/libexec/site-packages/django/db/models/query.py", line 394, in create
    obj.save(force_insert=True, using=self.db)
  File "/usr/local/Cellar/pypy/5.8.0/libexec/site-packages/django/db/models/base.py", line 807, in save
    force_update=force_update, update_fields=update_fields)
  File "/usr/local/Cellar/pypy/5.8.0/libexec/site-packages/django/db/models/base.py", line 837, in save_base
    updated = self._save_table(raw, cls, force_insert, force_update, using, update_fields)
  File "/usr/local/Cellar/pypy/5.8.0/libexec/site-packages/django/db/models/base.py", line 923, in _save_table
    result = self._do_insert(cls._base_manager, using, fields, update_pk, raw)
  File "/usr/local/Cellar/pypy/5.8.0/libexec/site-packages/django/db/models/base.py", line 962, in _do_insert
    using=using, raw=raw)
  File "/usr/local/Cellar/pypy/5.8.0/libexec/site-packages/django/db/models/manager.py", line 85, in manager_method
    return getattr(self.get_queryset(), name)(*args, **kwargs)
  File "/usr/local/Cellar/pypy/5.8.0/libexec/site-packages/django/db/models/query.py", line 1076, in _insert
    return query.get_compiler(using=using).execute_sql(return_id)
  File "/usr/local/Cellar/pypy/5.8.0/libexec/site-packages/django/db/models/sql/compiler.py", line 1099, in execute_sql
    cursor.execute(sql, params)
  File "/usr/local/Cellar/pypy/5.8.0/libexec/site-packages/django/db/backends/utils.py", line 80, in execute
    return super(CursorDebugWrapper, self).execute(sql, params)
  File "/usr/local/Cellar/pypy/5.8.0/libexec/site-packages/django/db/backends/utils.py", line 65, in execute
    return self.cursor.execute(sql, params)
  File "/usr/local/Cellar/pypy/5.8.0/libexec/site-packages/django/db/utils.py", line 94, in __exit__
    six.reraise(dj_exc_type, dj_exc_value, traceback)
  File "/usr/local/Cellar/pypy/5.8.0/libexec/site-packages/django/db/backends/utils.py", line 65, in execute
    return self.cursor.execute(sql, params)
  File "/usr/local/Cellar/pypy/5.8.0/libexec/site-packages/django/db/backends/mysql/base.py", line 101, in execute
    return self.cursor.execute(query, args)
  File "/usr/local/Cellar/pypy/5.8.0/libexec/site-packages/pymysql/cursors.py", line 166, in execute
    result = self._query(query)
  File "/usr/local/Cellar/pypy/5.8.0/libexec/site-packages/pymysql/cursors.py", line 322, in _query
    conn.query(q)
  File "/usr/local/Cellar/pypy/5.8.0/libexec/site-packages/pymysql/connections.py", line 856, in query
    self._affected_rows = self._read_query_result(unbuffered=unbuffered)
  File "/usr/local/Cellar/pypy/5.8.0/libexec/site-packages/pymysql/connections.py", line 1057, in _read_query_result
    result.read()
  File "/usr/local/Cellar/pypy/5.8.0/libexec/site-packages/pymysql/connections.py", line 1340, in read
    first_packet = self.connection._read_packet()
  File "/usr/local/Cellar/pypy/5.8.0/libexec/site-packages/pymysql/connections.py", line 1014, in _read_packet
    packet.check_error()
  File "/usr/local/Cellar/pypy/5.8.0/libexec/site-packages/pymysql/connections.py", line 393, in check_error
    err.raise_mysql_exception(self._data)
  File "/usr/local/Cellar/pypy/5.8.0/libexec/site-packages/pymysql/err.py", line 107, in raise_mysql_exception
    raise errorclass(errno, errval)
ProgrammingError: (1146, u"Table 'deploysystem.cluster' doesn't exist")
2017-12-08 14:45:17,438 [Thread-4:123145326198784] [django.request:135] [exception:handle_uncaught_exception] [ERROR]- Internal Server Error: /server/CreateCluster
Traceback (most recent call last):
  File "/usr/local/Cellar/pypy/5.8.0/libexec/site-packages/django/core/handlers/exception.py", line 41, in inner
    response = get_response(request)
  File "/usr/local/Cellar/pypy/5.8.0/libexec/site-packages/django/core/handlers/base.py", line 187, in _get_response
    response = self.process_exception_by_middleware(e, request)
  File "/usr/local/Cellar/pypy/5.8.0/libexec/site-packages/django/core/handlers/base.py", line 185, in _get_response
    response = wrapped_callback(request, *callback_args, **callback_kwargs)
  File "/usr/local/Cellar/pypy/5.8.0/libexec/site-packages/django/views/decorators/csrf.py", line 58, in wrapped_view
    return view_func(*args, **kwargs)
  File "/usr/local/Cellar/pypy/5.8.0/libexec/site-packages/django/views/generic/base.py", line 68, in view
    return self.dispatch(request, *args, **kwargs)
  File "/usr/local/Cellar/pypy/5.8.0/libexec/site-packages/rest_framework/views.py", line 489, in dispatch
    response = self.handle_exception(exc)
  File "/usr/local/Cellar/pypy/5.8.0/libexec/site-packages/rest_framework/views.py", line 449, in handle_exception
    self.raise_uncaught_exception(exc)
  File "/usr/local/Cellar/pypy/5.8.0/libexec/site-packages/rest_framework/views.py", line 486, in dispatch
    response = handler(request, *args, **kwargs)
  File "/Users/benson/Projects/MikasonOperBackend/server/cluster_api_views.py", line 25, in post
    serializer.save()
  File "/usr/local/Cellar/pypy/5.8.0/libexec/site-packages/rest_framework/serializers.py", line 215, in save
    self.instance = self.create(validated_data)
  File "/usr/local/Cellar/pypy/5.8.0/libexec/site-packages/rest_framework/serializers.py", line 916, in create
    instance = ModelClass.objects.create(**validated_data)
  File "/usr/local/Cellar/pypy/5.8.0/libexec/site-packages/django/db/models/manager.py", line 85, in manager_method
    return getattr(self.get_queryset(), name)(*args, **kwargs)
  File "/usr/local/Cellar/pypy/5.8.0/libexec/site-packages/django/db/models/query.py", line 394, in create
    obj.save(force_insert=True, using=self.db)
  File "/usr/local/Cellar/pypy/5.8.0/libexec/site-packages/django/db/models/base.py", line 807, in save
    force_update=force_update, update_fields=update_fields)
  File "/usr/local/Cellar/pypy/5.8.0/libexec/site-packages/django/db/models/base.py", line 837, in save_base
    updated = self._save_table(raw, cls, force_insert, force_update, using, update_fields)
  File "/usr/local/Cellar/pypy/5.8.0/libexec/site-packages/django/db/models/base.py", line 923, in _save_table
    result = self._do_insert(cls._base_manager, using, fields, update_pk, raw)
  File "/usr/local/Cellar/pypy/5.8.0/libexec/site-packages/django/db/models/base.py", line 962, in _do_insert
    using=using, raw=raw)
  File "/usr/local/Cellar/pypy/5.8.0/libexec/site-packages/django/db/models/manager.py", line 85, in manager_method
    return getattr(self.get_queryset(), name)(*args, **kwargs)
  File "/usr/local/Cellar/pypy/5.8.0/libexec/site-packages/django/db/models/query.py", line 1076, in _insert
    return query.get_compiler(using=using).execute_sql(return_id)
  File "/usr/local/Cellar/pypy/5.8.0/libexec/site-packages/django/db/models/sql/compiler.py", line 1099, in execute_sql
    cursor.execute(sql, params)
  File "/usr/local/Cellar/pypy/5.8.0/libexec/site-packages/django/db/backends/utils.py", line 80, in execute
    return super(CursorDebugWrapper, self).execute(sql, params)
  File "/usr/local/Cellar/pypy/5.8.0/libexec/site-packages/django/db/backends/utils.py", line 65, in execute
    return self.cursor.execute(sql, params)
  File "/usr/local/Cellar/pypy/5.8.0/libexec/site-packages/django/db/utils.py", line 94, in __exit__
    six.reraise(dj_exc_type, dj_exc_value, traceback)
  File "/usr/local/Cellar/pypy/5.8.0/libexec/site-packages/django/db/backends/utils.py", line 65, in execute
    return self.cursor.execute(sql, params)
  File "/usr/local/Cellar/pypy/5.8.0/libexec/site-packages/django/db/backends/mysql/base.py", line 101, in execute
    return self.cursor.execute(query, args)
  File "/usr/local/Cellar/pypy/5.8.0/libexec/site-packages/pymysql/cursors.py", line 166, in execute
    result = self._query(query)
  File "/usr/local/Cellar/pypy/5.8.0/libexec/site-packages/pymysql/cursors.py", line 322, in _query
    conn.query(q)
  File "/usr/local/Cellar/pypy/5.8.0/libexec/site-packages/pymysql/connections.py", line 856, in query
    self._affected_rows = self._read_query_result(unbuffered=unbuffered)
  File "/usr/local/Cellar/pypy/5.8.0/libexec/site-packages/pymysql/connections.py", line 1057, in _read_query_result
    result.read()
  File "/usr/local/Cellar/pypy/5.8.0/libexec/site-packages/pymysql/connections.py", line 1340, in read
    first_packet = self.connection._read_packet()
  File "/usr/local/Cellar/pypy/5.8.0/libexec/site-packages/pymysql/connections.py", line 1014, in _read_packet
    packet.check_error()
  File "/usr/local/Cellar/pypy/5.8.0/libexec/site-packages/pymysql/connections.py", line 393, in check_error
    err.raise_mysql_exception(self._data)
  File "/usr/local/Cellar/pypy/5.8.0/libexec/site-packages/pymysql/err.py", line 107, in raise_mysql_exception
    raise errorclass(errno, errval)
InternalError: (1054, u"Unknown column 'createdata' in 'field list'")
2017-12-11 21:52:19,758 [Thread-4:123145474117632] [django.request:135] [exception:handle_uncaught_exception] [ERROR]- Internal Server Error: /server/BindServer
Traceback (most recent call last):
  File "/usr/local/Cellar/pypy/5.8.0/libexec/site-packages/django/core/handlers/exception.py", line 41, in inner
    response = get_response(request)
  File "/usr/local/Cellar/pypy/5.8.0/libexec/site-packages/django/core/handlers/base.py", line 187, in _get_response
    response = self.process_exception_by_middleware(e, request)
  File "/usr/local/Cellar/pypy/5.8.0/libexec/site-packages/django/core/handlers/base.py", line 185, in _get_response
    response = wrapped_callback(request, *callback_args, **callback_kwargs)
  File "/usr/local/Cellar/pypy/5.8.0/libexec/site-packages/django/views/decorators/csrf.py", line 58, in wrapped_view
    return view_func(*args, **kwargs)
  File "/usr/local/Cellar/pypy/5.8.0/libexec/site-packages/django/views/generic/base.py", line 68, in view
    return self.dispatch(request, *args, **kwargs)
  File "/usr/local/Cellar/pypy/5.8.0/libexec/site-packages/rest_framework/views.py", line 489, in dispatch
    response = self.handle_exception(exc)
  File "/usr/local/Cellar/pypy/5.8.0/libexec/site-packages/rest_framework/views.py", line 449, in handle_exception
    self.raise_uncaught_exception(exc)
  File "/usr/local/Cellar/pypy/5.8.0/libexec/site-packages/rest_framework/views.py", line 486, in dispatch
    response = handler(request, *args, **kwargs)
  File "/Users/benson/Projects/MikasonOperBackend/server/cluster_api_views.py", line 172, in post
    serializer.save()
  File "/usr/local/Cellar/pypy/5.8.0/libexec/site-packages/rest_framework/serializers.py", line 215, in save
    self.instance = self.create(validated_data)
  File "/usr/local/Cellar/pypy/5.8.0/libexec/site-packages/rest_framework/serializers.py", line 916, in create
    instance = ModelClass.objects.create(**validated_data)
  File "/usr/local/Cellar/pypy/5.8.0/libexec/site-packages/django/db/models/manager.py", line 85, in manager_method
    return getattr(self.get_queryset(), name)(*args, **kwargs)
  File "/usr/local/Cellar/pypy/5.8.0/libexec/site-packages/django/db/models/query.py", line 394, in create
    obj.save(force_insert=True, using=self.db)
  File "/usr/local/Cellar/pypy/5.8.0/libexec/site-packages/django/db/models/base.py", line 807, in save
    force_update=force_update, update_fields=update_fields)
  File "/usr/local/Cellar/pypy/5.8.0/libexec/site-packages/django/db/models/base.py", line 837, in save_base
    updated = self._save_table(raw, cls, force_insert, force_update, using, update_fields)
  File "/usr/local/Cellar/pypy/5.8.0/libexec/site-packages/django/db/models/base.py", line 923, in _save_table
    result = self._do_insert(cls._base_manager, using, fields, update_pk, raw)
  File "/usr/local/Cellar/pypy/5.8.0/libexec/site-packages/django/db/models/base.py", line 962, in _do_insert
    using=using, raw=raw)
  File "/usr/local/Cellar/pypy/5.8.0/libexec/site-packages/django/db/models/manager.py", line 85, in manager_method
    return getattr(self.get_queryset(), name)(*args, **kwargs)
  File "/usr/local/Cellar/pypy/5.8.0/libexec/site-packages/django/db/models/query.py", line 1076, in _insert
    return query.get_compiler(using=using).execute_sql(return_id)
  File "/usr/local/Cellar/pypy/5.8.0/libexec/site-packages/django/db/models/sql/compiler.py", line 1099, in execute_sql
    cursor.execute(sql, params)
  File "/usr/local/Cellar/pypy/5.8.0/libexec/site-packages/django/db/backends/utils.py", line 80, in execute
    return super(CursorDebugWrapper, self).execute(sql, params)
  File "/usr/local/Cellar/pypy/5.8.0/libexec/site-packages/django/db/backends/utils.py", line 65, in execute
    return self.cursor.execute(sql, params)
  File "/usr/local/Cellar/pypy/5.8.0/libexec/site-packages/django/db/utils.py", line 94, in __exit__
    six.reraise(dj_exc_type, dj_exc_value, traceback)
  File "/usr/local/Cellar/pypy/5.8.0/libexec/site-packages/django/db/backends/utils.py", line 65, in execute
    return self.cursor.execute(sql, params)
  File "/usr/local/Cellar/pypy/5.8.0/libexec/site-packages/django/db/backends/mysql/base.py", line 101, in execute
    return self.cursor.execute(query, args)
  File "/usr/local/Cellar/pypy/5.8.0/libexec/site-packages/pymysql/cursors.py", line 166, in execute
    result = self._query(query)
  File "/usr/local/Cellar/pypy/5.8.0/libexec/site-packages/pymysql/cursors.py", line 322, in _query
    conn.query(q)
  File "/usr/local/Cellar/pypy/5.8.0/libexec/site-packages/pymysql/connections.py", line 856, in query
    self._affected_rows = self._read_query_result(unbuffered=unbuffered)
  File "/usr/local/Cellar/pypy/5.8.0/libexec/site-packages/pymysql/connections.py", line 1057, in _read_query_result
    result.read()
  File "/usr/local/Cellar/pypy/5.8.0/libexec/site-packages/pymysql/connections.py", line 1340, in read
    first_packet = self.connection._read_packet()
  File "/usr/local/Cellar/pypy/5.8.0/libexec/site-packages/pymysql/connections.py", line 1014, in _read_packet
    packet.check_error()
  File "/usr/local/Cellar/pypy/5.8.0/libexec/site-packages/pymysql/connections.py", line 393, in check_error
    err.raise_mysql_exception(self._data)
  File "/usr/local/Cellar/pypy/5.8.0/libexec/site-packages/pymysql/err.py", line 107, in raise_mysql_exception
    raise errorclass(errno, errval)
InternalError: (1054, u"Unknown column 'moduleId' in 'field list'")
2017-12-12 11:32:46,577 [Thread-2:123145414688768] [django.request:135] [exception:handle_uncaught_exception] [ERROR]- Internal Server Error: /server/GetCluster
Traceback (most recent call last):
  File "/usr/local/Cellar/pypy/5.8.0/libexec/site-packages/django/core/handlers/exception.py", line 41, in inner
    response = get_response(request)
  File "/usr/local/Cellar/pypy/5.8.0/libexec/site-packages/django/core/handlers/base.py", line 187, in _get_response
    response = self.process_exception_by_middleware(e, request)
  File "/usr/local/Cellar/pypy/5.8.0/libexec/site-packages/django/core/handlers/base.py", line 185, in _get_response
    response = wrapped_callback(request, *callback_args, **callback_kwargs)
  File "/usr/local/Cellar/pypy/5.8.0/libexec/site-packages/django/views/decorators/csrf.py", line 58, in wrapped_view
    return view_func(*args, **kwargs)
  File "/usr/local/Cellar/pypy/5.8.0/libexec/site-packages/django/views/generic/base.py", line 68, in view
    return self.dispatch(request, *args, **kwargs)
  File "/usr/local/Cellar/pypy/5.8.0/libexec/site-packages/rest_framework/views.py", line 489, in dispatch
    response = self.handle_exception(exc)
  File "/usr/local/Cellar/pypy/5.8.0/libexec/site-packages/rest_framework/views.py", line 449, in handle_exception
    self.raise_uncaught_exception(exc)
  File "/usr/local/Cellar/pypy/5.8.0/libexec/site-packages/rest_framework/views.py", line 486, in dispatch
    response = handler(request, *args, **kwargs)
  File "/Users/benson/Projects/MikasonOperBackend/server/cluster_api_views.py", line 92, in post
    'server': server[0]
IndexError: tuple index out of range
